2019-10-18 10:08:13,650 ERROR: Exception on /simple.png [GET] [in /home/knerr/repos/mydrop/mytrilog/venv/lib/python3.5/site-packages/flask/app.py:1891]
Traceback (most recent call last):
  File "/home/knerr/repos/mydrop/mytrilog/venv/lib/python3.5/site-packages/flask/app.py", line 2446, in wsgi_app
    response = self.full_dispatch_request()
  File "/home/knerr/repos/mydrop/mytrilog/venv/lib/python3.5/site-packages/flask/app.py", line 1951, in full_dispatch_request
    rv = self.handle_user_exception(e)
  File "/home/knerr/repos/mydrop/mytrilog/venv/lib/python3.5/site-packages/flask/app.py", line 1820, in handle_user_exception
    reraise(exc_type, exc_value, tb)
  File "/home/knerr/repos/mydrop/mytrilog/venv/lib/python3.5/site-packages/flask/_compat.py", line 39, in reraise
    raise value
  File "/home/knerr/repos/mydrop/mytrilog/venv/lib/python3.5/site-packages/flask/app.py", line 1949, in full_dispatch_request
    rv = self.dispatch_request()
  File "/home/knerr/repos/mydrop/mytrilog/venv/lib/python3.5/site-packages/flask/app.py", line 1935, in dispatch_request
    return self.view_functions[rule.endpoint](**req.view_args)
  File "/home/knerr/repos/mydrop/mytrilog/app/routes.py", line 195, in simple
    from matplotlib.backends.backend_agg import FigureCanvasAgg as FigureCanvas
ImportError: No module named 'matplotlib'
2019-10-18 10:09:18,127 INFO: MyTriLog startup... [in /home/knerr/repos/mydrop/mytrilog/app/__init__.py:49]
2019-10-18 10:20:05,007 INFO: MyTriLog startup... [in /home/knerr/repos/mydrop/mytrilog/app/__init__.py:49]
2019-10-18 10:20:09,567 ERROR: Exception on / [GET] [in /home/knerr/repos/mydrop/mytrilog/venv/lib/python3.5/site-packages/flask/app.py:1891]
Traceback (most recent call last):
  File "/home/knerr/repos/mydrop/mytrilog/venv/lib/python3.5/site-packages/flask/app.py", line 2446, in wsgi_app
    response = self.full_dispatch_request()
  File "/home/knerr/repos/mydrop/mytrilog/venv/lib/python3.5/site-packages/flask/app.py", line 1951, in full_dispatch_request
    rv = self.handle_user_exception(e)
  File "/home/knerr/repos/mydrop/mytrilog/venv/lib/python3.5/site-packages/flask/app.py", line 1820, in handle_user_exception
    reraise(exc_type, exc_value, tb)
  File "/home/knerr/repos/mydrop/mytrilog/venv/lib/python3.5/site-packages/flask/_compat.py", line 39, in reraise
    raise value
  File "/home/knerr/repos/mydrop/mytrilog/venv/lib/python3.5/site-packages/flask/app.py", line 1949, in full_dispatch_request
    rv = self.dispatch_request()
  File "/home/knerr/repos/mydrop/mytrilog/venv/lib/python3.5/site-packages/flask/app.py", line 1935, in dispatch_request
    return self.view_functions[rule.endpoint](**req.view_args)
  File "/home/knerr/repos/mydrop/mytrilog/venv/lib/python3.5/site-packages/flask_login/utils.py", line 261, in decorated_view
    return func(*args, **kwargs)
  File "/home/knerr/repos/mydrop/mytrilog/app/routes.py", line 64, in index
    png_output = png_output.getvalue().encode("base64")
AttributeError: 'bytes' object has no attribute 'encode'
2019-10-18 10:20:40,962 INFO: MyTriLog startup... [in /home/knerr/repos/mydrop/mytrilog/app/__init__.py:49]
2019-10-18 10:20:43,270 ERROR: Exception on / [GET] [in /home/knerr/repos/mydrop/mytrilog/venv/lib/python3.5/site-packages/flask/app.py:1891]
Traceback (most recent call last):
  File "/home/knerr/repos/mydrop/mytrilog/venv/lib/python3.5/site-packages/flask/app.py", line 2446, in wsgi_app
    response = self.full_dispatch_request()
  File "/home/knerr/repos/mydrop/mytrilog/venv/lib/python3.5/site-packages/flask/app.py", line 1951, in full_dispatch_request
    rv = self.handle_user_exception(e)
  File "/home/knerr/repos/mydrop/mytrilog/venv/lib/python3.5/site-packages/flask/app.py", line 1820, in handle_user_exception
    reraise(exc_type, exc_value, tb)
  File "/home/knerr/repos/mydrop/mytrilog/venv/lib/python3.5/site-packages/flask/_compat.py", line 39, in reraise
    raise value
  File "/home/knerr/repos/mydrop/mytrilog/venv/lib/python3.5/site-packages/flask/app.py", line 1949, in full_dispatch_request
    rv = self.dispatch_request()
  File "/home/knerr/repos/mydrop/mytrilog/venv/lib/python3.5/site-packages/flask/app.py", line 1935, in dispatch_request
    return self.view_functions[rule.endpoint](**req.view_args)
  File "/home/knerr/repos/mydrop/mytrilog/venv/lib/python3.5/site-packages/flask_login/utils.py", line 261, in decorated_view
    return func(*args, **kwargs)
  File "/home/knerr/repos/mydrop/mytrilog/app/routes.py", line 67, in index
    prev_url=prev_url, img_data=urllib.quote(png_output.rstrip('\n')))
NameError: name 'urllib' is not defined
2019-10-18 10:20:58,457 INFO: MyTriLog startup... [in /home/knerr/repos/mydrop/mytrilog/app/__init__.py:49]
2019-10-18 10:21:00,445 ERROR: Exception on / [GET] [in /home/knerr/repos/mydrop/mytrilog/venv/lib/python3.5/site-packages/flask/app.py:1891]
Traceback (most recent call last):
  File "/home/knerr/repos/mydrop/mytrilog/venv/lib/python3.5/site-packages/flask/app.py", line 2446, in wsgi_app
    response = self.full_dispatch_request()
  File "/home/knerr/repos/mydrop/mytrilog/venv/lib/python3.5/site-packages/flask/app.py", line 1951, in full_dispatch_request
    rv = self.handle_user_exception(e)
  File "/home/knerr/repos/mydrop/mytrilog/venv/lib/python3.5/site-packages/flask/app.py", line 1820, in handle_user_exception
    reraise(exc_type, exc_value, tb)
  File "/home/knerr/repos/mydrop/mytrilog/venv/lib/python3.5/site-packages/flask/_compat.py", line 39, in reraise
    raise value
  File "/home/knerr/repos/mydrop/mytrilog/venv/lib/python3.5/site-packages/flask/app.py", line 1949, in full_dispatch_request
    rv = self.dispatch_request()
  File "/home/knerr/repos/mydrop/mytrilog/venv/lib/python3.5/site-packages/flask/app.py", line 1935, in dispatch_request
    return self.view_functions[rule.endpoint](**req.view_args)
  File "/home/knerr/repos/mydrop/mytrilog/venv/lib/python3.5/site-packages/flask_login/utils.py", line 261, in decorated_view
    return func(*args, **kwargs)
  File "/home/knerr/repos/mydrop/mytrilog/app/routes.py", line 68, in index
    prev_url=prev_url, img_data=urllib.quote(png_output.rstrip('\n')))
AttributeError: module 'urllib' has no attribute 'quote'
2019-10-18 10:23:21,545 INFO: MyTriLog startup... [in /home/knerr/repos/mydrop/mytrilog/app/__init__.py:49]
2019-10-18 10:23:24,732 ERROR: Exception on / [GET] [in /home/knerr/repos/mydrop/mytrilog/venv/lib/python3.5/site-packages/flask/app.py:1891]
Traceback (most recent call last):
  File "/home/knerr/repos/mydrop/mytrilog/venv/lib/python3.5/site-packages/flask/app.py", line 2446, in wsgi_app
    response = self.full_dispatch_request()
  File "/home/knerr/repos/mydrop/mytrilog/venv/lib/python3.5/site-packages/flask/app.py", line 1951, in full_dispatch_request
    rv = self.handle_user_exception(e)
  File "/home/knerr/repos/mydrop/mytrilog/venv/lib/python3.5/site-packages/flask/app.py", line 1820, in handle_user_exception
    reraise(exc_type, exc_value, tb)
  File "/home/knerr/repos/mydrop/mytrilog/venv/lib/python3.5/site-packages/flask/_compat.py", line 39, in reraise
    raise value
  File "/home/knerr/repos/mydrop/mytrilog/venv/lib/python3.5/site-packages/flask/app.py", line 1949, in full_dispatch_request
    rv = self.dispatch_request()
  File "/home/knerr/repos/mydrop/mytrilog/venv/lib/python3.5/site-packages/flask/app.py", line 1935, in dispatch_request
    return self.view_functions[rule.endpoint](**req.view_args)
  File "/home/knerr/repos/mydrop/mytrilog/venv/lib/python3.5/site-packages/flask_login/utils.py", line 261, in decorated_view
    return func(*args, **kwargs)
  File "/home/knerr/repos/mydrop/mytrilog/app/routes.py", line 68, in index
    prev_url=prev_url, img_data=urllib.quote(png_output.rstrip('\n')))
NameError: name 'urllib' is not defined
2019-10-18 10:23:49,744 INFO: MyTriLog startup... [in /home/knerr/repos/mydrop/mytrilog/app/__init__.py:49]
2019-10-18 10:23:52,457 ERROR: Exception on / [GET] [in /home/knerr/repos/mydrop/mytrilog/venv/lib/python3.5/site-packages/flask/app.py:1891]
Traceback (most recent call last):
  File "/home/knerr/repos/mydrop/mytrilog/venv/lib/python3.5/site-packages/flask/app.py", line 2446, in wsgi_app
    response = self.full_dispatch_request()
  File "/home/knerr/repos/mydrop/mytrilog/venv/lib/python3.5/site-packages/flask/app.py", line 1951, in full_dispatch_request
    rv = self.handle_user_exception(e)
  File "/home/knerr/repos/mydrop/mytrilog/venv/lib/python3.5/site-packages/flask/app.py", line 1820, in handle_user_exception
    reraise(exc_type, exc_value, tb)
  File "/home/knerr/repos/mydrop/mytrilog/venv/lib/python3.5/site-packages/flask/_compat.py", line 39, in reraise
    raise value
  File "/home/knerr/repos/mydrop/mytrilog/venv/lib/python3.5/site-packages/flask/app.py", line 1949, in full_dispatch_request
    rv = self.dispatch_request()
  File "/home/knerr/repos/mydrop/mytrilog/venv/lib/python3.5/site-packages/flask/app.py", line 1935, in dispatch_request
    return self.view_functions[rule.endpoint](**req.view_args)
  File "/home/knerr/repos/mydrop/mytrilog/venv/lib/python3.5/site-packages/flask_login/utils.py", line 261, in decorated_view
    return func(*args, **kwargs)
  File "/home/knerr/repos/mydrop/mytrilog/app/routes.py", line 68, in index
    prev_url=prev_url, img_data=urllib3.quote(png_output.rstrip('\n')))
AttributeError: module 'urllib3' has no attribute 'quote'
2019-10-18 10:24:37,119 INFO: MyTriLog startup... [in /home/knerr/repos/mydrop/mytrilog/app/__init__.py:49]
